Workbook

Sheet Planilha1
A1: PAI | B1: PRODUTO | C1: À PRAZO | D1: À VISTA 7% | E1: Sugestão de preço final | F1: Obs
A2: 110262 | B2: KIT CARENAGEM 9 PEÇAS PRO TORK CB 300R 2010/12 | C2: 279.46 | D2: 259.8978 | E2: 399.9
A3: 110731A | B3: CAPACETE FECHADO PRO TORK SPORT MOTO 788 | C3: 81.62 | D3: 75.9066 | E3: 89.9
A4: 112481 | B4: Kit Plástico Carenagem Pro Tork Completo Biz 100 1998 a 2005 | C4: 300.97 | D4: 279.9021 | E4: 329.9
A5: 112490 | B5: KIT CARENAGEM 3 PEÇAS PRO TORK TITAN 2000/04 | C5: 107.41 | D5: 99.8913 | E5: 219.9
A6: 115826A | B6: CAPACETE ABERTO PRO TORK LIBERTY SOLID | C6: 75.17 | D6: 69.9081 | E6: 89.9
A7: 116086A | B7: CAPACETE FECHADO PRO TORK R8 | C7: 128.93 | D7: 119.9049 | E7: 144.9 | F7: PRINCIPAIS
A8: 116186A | B8: CAPACETE ESCAMOTEÁVEL PRO TORK V-PRO JET 3 | C8: 198.82 | D8: 184.9026 | E8: 239.9 | F8: PRINCIPAIS
A9: 116674A | B9: CAPACETE FECHADO INFANTIL PRO TORK LIBERTY FOUR KIDS SOLID VISEIRA FUMÊ | C9: 80.54 | D9: 74.9022 | E9: 89.9
A10: 116690A | B10: CAPACETE FECHADO PRO TORK LIBERTY MX VISION PRO VISEIRA FUMÊ | C10: 145.06 | D10: 134.9058 | E10: 159.9 | F10: PRINCIPAIS
A11: 116735A | B11: Capacete Moto Escamoteável V-Pro Jet 3 Robocop Pro Tork Fechado Viseira Fumê Sem Óculos Interno | C11: 209.57 | D11: 194.9001 | E11: 229.9
A12: 116746A | B12: Capacete Moto Fechado Masculino E Feminino Pro Tork R8 Viseira Fumê | C12: 128.93 | D12: 119.9049 | E12: 144.9
A13: 117524A | B13: Capacete Escamoteável Robocop Articulado Pro Tork Attack Evo Fosco Masculino e Feminino | C13: 302.04 | D13: 280.8972 | E13: 339.9 | F13: VERIFICAR
A14: 117541A | B14: CAPACETE FECHADO MIXS START | C14: 80.54 | D14: 74.9022 | E14: 89.9
A15: 119768A | B15: CAPACETE FECHADO MIXS MX2 STORM BRILHANTE | C15: 128.92 | D15: 119.8956 | E15: 149.9 | F15: PRINCIPAIS
A16: 119776A | B16: CAPACETE FECHADO MIXS MX2 STORM FOSCO | C16: 128.92 | D16: 119.8956 | E16: 149.9 | F16: PRINCIPAIS
A17: 119804 | B17: ESCAPAMENTO PRO TORK COMPETITION [CURVA PRETA] TITAN 125 KS/KSE 2000/04 / FAN 125 2005/08 | C17: 118.17 | D17: 109.8981 | E17: 174.9
A18: 119816A | B18: ESCAPAMENTO PRO TORK COMPETITION [CURVA PRETA] TITAN 150 KS/ES 2004/08 | C18: 118.17 | D18: 109.8981 | E18: 159.9
A19: 119822 | B19: ESCAPAMENTO PRO TORK COMPETITION [CURVA PRETA] TITAN 150 / FAN 125/150 KS/ES 2009/13 | C19: 118.17 | D19: 109.8981 | E19: 174.9
A20: 119931 | B20: ESCAPAMENTO PRO TORK COMPETITION [CURVA CROMADA] TITAN 150 KS/ES 2004/08 | C20: 128.92 | D20: 119.8956 | E20: 189.9
A21: 119933 | B21: Escapamento Pro Tork Competition Fan 160 E Start 160 2015 À 2024 | C21: 128.92 | D21: 119.8956 | E21: 149.9
A22: 119934 | B22: ESCAPAMENTO PRO TORK COMPETITION [CURVA CROMADA] POP 110 2016/22 | C22: 107.41 | D22: 99.8913 | E22: 159.9
A23: 119943 | B23: Capacete Pro Tork Feminino Moto Fechado Evolution G8 Evo | C23: 204.19 | D23: 189.8967 | E23: 229.9
A24: 119944 | B24: CAPACETE FECHADO PRO TORK EVOLUTION 788 G8 EVO SOLID | C24: 204.19 | D24: 189.8967 | E24: 229 | F24: PRINCIPAIS
A25: 119945 | B25: CAPACETE FECHADO PRO TORK JETT EVO LINE BRILHANTE | C25: 182.68 | D25: 169.8924 | E25: 214.9 | F25: PRINCIPAIS
A26: 119949 | B26: CAPACETE ABERTO PRO TORK NEW ATOMIC ELITE | C26: 112.79 | D26: 104.8947 | E26: 129.9 | F26: PRINCIPAIS
A27: 119952 | B27: Capacete Motocross Trilha Off Road Pro Tork Fast 788 Solid Feminino Masculino Novo Lançamento | C27: 225.69 | D27: 209.8917 | E27: 239.9
A28: 119954 | B28: CAPACETE ABERTO PRO TORK NEW LIBERTY 3 ELITE | C28: 102.04 | D28: 94.8972 | E28: 109.9
A29: 120220 | B29: CAPACETE CUSTOM PRO TORK COQUINHO | C29: 63.34 | D29: 58.9062 | E29: 79.9 | F29: PRINCIPAIS
A30: 120499 | B30: CAPACETE ABERTO MIXS WAY | C30: 85.91 | D30: 79.8963 | E30: 109.9
A31: 121016 | B31: CAPACETE OFF ROAD PRO TORK FAST TECH FANTASY LIMITED EDITION | C31: 225.69 | D31: 209.8917 | E31: 239.9 | F31: PRINCIPAIS
A32: 121017 | B32: CAPACETE OFF ROAD PRO TORK FAST TECH FANTASY LIMITED EDITION | C32: 225.69 | D32: 209.8917 | E32: 239.9 | F32: PRINCIPAIS
A33: 121059 | B33: CAPACETE ABERTO PRO TORK NEW LIBERTY 3 SOLID VISEIRA FUMÊ | C33: 85.91 | D33: 79.8963 | E33: 109.9
A34: 121331 | B34: ESCAPAMENTO GEMOTO RACING TITAN 150 KS/ES 2004/08 | C34: 150.43 | D34: 139.8999 | E34: 209.9
A35: 121439 | B35: ESCAPAMENTO GEMOTO RACING 3 TRIOVAL [CURVA CROMADA] CBX 250 TWISTER | C35: 214.94 | D35: 199.8942 | E35: 299.9
A36: 1223 | B36: Ponteira Pro Tork Modelo Original CBX 250 TWISTER 2002 à 2008 | C36: 177.32 | D36: 164.9076 | E36: 199.9
A37: 122310 | B37: ESCAPAMENTO GEMOTO RACING TITAN 160 2016/20 / FAN 160 2018/22 | C37: 171.93 | D37: 159.8949 | E37: 229.9
A38: 122700 | B38: ESCAPAMENTO GEMOTO RACING 3 TRIOVAL [CURVA CROMADA] YBR 125 2000/08 | C38: 171.93 | D38: 159.8949 | E38: 229.9
A39: 123496 | B39: KIT CARENAGEM 3 PEÇAS CROMO FORTE YBR 125 2000/08 | C39: 139.67 | D39: 129.8931 | E39: 209.9
A40: 123901 | B40: Capacete Escamoteável Pro Tork V-Pro Jet Factor Sem Óculos Interno | C40: 204.19 | D40: 189.8967 | E40: 219.9
...

Sheet ABAIXO DO MERCADO 
A1: PAI | B1: PRODUTO | C1: À PRAZO | D1: À VISTA 7% | E1: OBSERVAÇÃO
A2: 112181 | B2: BAÚ PLÁSTICO SUPERIOR 135 LITROS PRO TORK | C2: 322.47 | D2: =C2-(C2*7%) -> 299.8971 | E2: PREÇO ABAIXO DO MERCADO | F2: =_xlfn.XLOOKUP(A2,Planilha1!A:A,Planilha1!E:E) -> #N/A | G2: =_xlfn.XLOOKUP(A2,[1]Planilha1!$A:$A,[1]Planilha1!$C:$C) -> MANTER
A3: 126767 | B3: CAPACETE MOTOCROSS PRO TORK FAST NEXT BRILHANTE | C3: 219.24 | D3: =C3-(C3*7%) -> 203.8932 | E3: PREÇO ABAIXO DO MERCADO | F3: =_xlfn.XLOOKUP(A3,Planilha1!A:A,Planilha1!E:E) -> 239.9 | G3: =_xlfn.XLOOKUP(A3,[1]Planilha1!$A:$A,[1]Planilha1!$C:$C) -> 239.9
A4: 119949 | B4: CAPACETE ABERTO PRO TORK NEW ATOMIC ELITE | C4: 112.79 | D4: =C4-(C4*7%) -> 104.8947 | E4: PREÇO ABAIXO DO MERCADO | F4: =_xlfn.XLOOKUP(A4,Planilha1!A:A,Planilha1!E:E) -> 129.9 | G4: =_xlfn.XLOOKUP(A4,[1]Planilha1!$A:$A,[1]Planilha1!$C:$C) -> 129.9
A5: 5478A | B5: CAPACETE ABERTO PRO TORK NEW ATOMIC SOLID FOSCO [SEM ADESIVO] | C5: 107.41 | D5: =C5-(C5*7%) -> 99.8913 | E5: PREÇO ABAIXO DO MERCADO | F5: =_xlfn.XLOOKUP(A5,Planilha1!A:A,Planilha1!E:E) -> 124.9 | G5: =_xlfn.XLOOKUP(A5,[1]Planilha1!$A:$A,[1]Planilha1!$C:$C) -> 124.9
A6: 126178 | B6: CAPACETE ABERTO PRO TORK NEW ATOMIC UNIVERSE BRILHANTE | C6: 107.41 | D6: =C6-(C6*7%) -> 99.8913 | E6: PREÇO ABAIXO DO MERCADO | F6: =_xlfn.XLOOKUP(A6,Planilha1!A:A,Planilha1!E:E) -> 124.9 | G6: =_xlfn.XLOOKUP(A6,[1]Planilha1!$A:$A,[1]Planilha1!$C:$C) -> 124.9
A7: 120220 | B7: CAPACETE CUSTOM PRO TORK COQUINHO | C7: 63.34 | D7: =C7-(C7*7%) -> 58.9062 | E7: PREÇO ABAIXO DO MERCADO | F7: =_xlfn.XLOOKUP(A7,Planilha1!A:A,Planilha1!E:E) -> 79.9 | G7: =_xlfn.XLOOKUP(A7,[1]Planilha1!$A:$A,[1]Planilha1!$C:$C) -> #N/A
A8: 116186A | B8: CAPACETE ESCAMOTEÁVEL PRO TORK V-PRO JET 3 | C8: 198.82 | D8: =C8-(C8*7%) -> 184.9026 | E8: PREÇO ABAIXO DO MERCADO | F8: =_xlfn.XLOOKUP(A8,Planilha1!A:A,Planilha1!E:E) -> 239.9 | G8: =_xlfn.XLOOKUP(A8,[1]Planilha1!$A:$A,[1]Planilha1!$C:$C) -> 239.9
A9: 5351A | B9: CAPACETE ESCAMOTEÁVEL PRO TORK V-PRO JET SOLID | C9: 155.81 | D9: =C9-(C9*7%) -> 144.9033 | E9: PREÇO ABAIXO DO MERCADO | F9: =_xlfn.XLOOKUP(A9,Planilha1!A:A,Planilha1!E:E) -> 169.9 | G9: =_xlfn.XLOOKUP(A9,[1]Planilha1!$A:$A,[1]Planilha1!$C:$C) -> 169.9
A10: 119768A | B10: CAPACETE FECHADO MIXS MX2 STORM BRILHANTE | C10: 128.92 | D10: =C10-(C10*7%) -> 119.8956 | E10: PREÇO ABAIXO DO MERCADO | F10: =_xlfn.XLOOKUP(A10,Planilha1!A:A,Planilha1!E:E) -> 149.9 | G10: =_xlfn.XLOOKUP(A10,[1]Planilha1!$A:$A,[1]Planilha1!$C:$C) -> 149.9
A11: 119776A | B11: CAPACETE FECHADO MIXS MX2 STORM FOSCO | C11: 128.92 | D11: =C11-(C11*7%) -> 119.8956 | E11: PREÇO ABAIXO DO MERCADO | F11: =_xlfn.XLOOKUP(A11,Planilha1!A:A,Planilha1!E:E) -> 149.9 | G11: =_xlfn.XLOOKUP(A11,[1]Planilha1!$A:$A,[1]Planilha1!$C:$C) -> 149.9
A12: 119944 | B12: CAPACETE FECHADO PRO TORK EVOLUTION 788 G8 EVO SOLID | C12: 204.19 | D12: =C12-(C12*7%) -> 189.8967 | E12: PREÇO ABAIXO DO MERCADO | F12: =_xlfn.XLOOKUP(A12,Planilha1!A:A,Planilha1!E:E) -> 229 | G12: =_xlfn.XLOOKUP(A12,[1]Planilha1!$A:$A,[1]Planilha1!$C:$C) -> 229
A13: 119945 | B13: CAPACETE FECHADO PRO TORK JETT EVO LINE BRILHANTE | C13: 182.68 | D13: =C13-(C13*7%) -> 169.8924 | E13: PREÇO ABAIXO DO MERCADO | F13: =_xlfn.XLOOKUP(A13,Planilha1!A:A,Planilha1!E:E) -> 214.9 | G13: =_xlfn.XLOOKUP(A13,[1]Planilha1!$A:$A,[1]Planilha1!$C:$C) -> 214.9
... A38: 110262 | B38: KIT CARENAGEM 9 PEÇAS PRO TORK CB 300R 2010/12 | C38: 279.46 | D38: =C38-(C38*7%) -> 259.8978 | E38: PREÇO ABAIXO DO MERCADO | F38: =_xlfn.XLOOKUP(A38,Planilha1!A:A,Planilha1!E:E) -> 399.9 | G38: =_xlfn.XLOOKUP(A38,[1]Planilha1!$A:$A,[1]Planilha1!$C:$C) -> 399.9
A39: 116746A | B39: Capacete Moto Fechado Masculino E Feminino Pro Tork R8 Viseira Fumê | C39: 128.93 | D39: 119.9049 | E39: ABAIXO DO MERCADO | F39: =_xlfn.XLOOKUP(A39,Planilha1!A:A,Planilha1!E:E) -> 144.9 | G39: =_xlfn.XLOOKUP(A39,[1]Planilha1!$A:$A,[1]Planilha1!$C:$C) -> 144.9
A40: 119943 | B40: Capacete Pro Tork Feminino Moto Fechado Evolution G8 Evo | C40: 204.19 | D40: 189.8967 | E40: ABAIXO DO MERCADO | F40: =_xlfn.XLOOKUP(A40,Planilha1!A:A,Planilha1!E:E) -> 229.9 | G40: =_xlfn.XLOOKUP(A40,[1]Planilha1!$A:$A,[1]Planilha1!$C:$C) -> 229
A41: 126199 | B41: Capacete Pro Tork Stealth Hawk Moto Moderno E Brilhante | C41: 216.02 | D41: 200.8986 | E41: ABAIXO DO MERCADO | F41: =_xlfn.XLOOKUP(A41,Planilha1!A:A,Planilha1!E:E) -> 239.9 | G41: =_xlfn.XLOOKUP(A41,[1]Planilha1!$A:$A,[1]Planilha1!$C:$C) -> 239.9
A42: 124963 | B42: Capacete Fechado Esportivo Stealth Concept Viseira Fumê | C42: 216.02 | D42: 200.8986 | E42: ABAIXO DO MERCADO | F42: =_xlfn.XLOOKUP(A42,Planilha1!A:A,Planilha1!E:E) -> 239.9 | G42: =_xlfn.XLOOKUP(A42,[1]Planilha1!$A:$A,[1]Planilha1!$C:$C) -> 239.9
A43: 124921 | B43: Capacete Moto Stealth Solid Pro Tork Motoqueiro Viseira Fumê | C43: 216.02 | D43: 200.8986 | E43: ABAIXO DO MERCADO | F43: =_xlfn.XLOOKUP(A43,Planilha1!A:A,Planilha1!E:E) -> 239.9 | G43: =_xlfn.XLOOKUP(A43,[1]Planilha1!$A:$A,[1]Planilha1!$C:$C) -> 239.9
A44: 116735A | B44: Capacete Moto Escamoteável V-Pro Jet 3 Robocop Pro Tork Fechado Viseira Fumê Sem Óculos Interno | C44: 209.57 | D44: 194.9001 | E44: ABAIXO DO MERCADO | F44: =_xlfn.XLOOKUP(A44,Planilha1!A:A,Planilha1!E:E) -> 229.9 | G44: =_xlfn.XLOOKUP(A44,[1]Planilha1!$A:$A,[1]Planilha1!$C:$C) -> 239.9
A45: 117524A | B45: Capacete Escamoteável Robocop Articulado Pro Tork Attack Evo Fosco Masculino e Feminino | C45: 302.04 | D45: 280.8972 | E45: ABAIXO DO MERCADO | F45: =_xlfn.XLOOKUP(A45,Planilha1!A:A,Planilha1!E:E) -> 339.9 | G45: =_xlfn.XLOOKUP(A45,[1]Planilha1!$A:$A,[1]Planilha1!$C:$C) -> 339.9
A46: 757A | B46: Capacete Pro Tork Fechado Trilha Enduro Liberty Mx Pro | C46: 91.29 | D46: 84.8997 | E46: ABAIXO DO MERCADO | F46: =_xlfn.XLOOKUP(A46,Planilha1!A:A,Planilha1!E:E) -> 109.9 | G46: =_xlfn.XLOOKUP(A46,[1]Planilha1!$A:$A,[1]Planilha1!$C:$C) -> 109.9
A47: 119952 | B47: Capacete Motocross Trilha Off Road Pro Tork Fast 788 Solid Feminino Masculino Novo Lançamento | C47: 225.69 | D47: 209.8917 | E47: ABAIXO DO MERCADO | F47: =_xlfn.XLOOKUP(A47,Planilha1!A:A,Planilha1!E:E) -> 239.9 | G47: =_xlfn.XLOOKUP(A47,[1]Planilha1!$A:$A,[1]Planilha1!$C:$C) -> 239.9
A48: 123901 | B48: Capacete Escamoteável Pro Tork V-Pro Jet Factor Sem Óculos Interno | C48: 204.19 | D48: 189.8967 | E48: ABAIXO DO MERCADO | F48: =_xlfn.XLOOKUP(A48,Planilha1!A:A,Planilha1!E:E) -> 219.9 | G48: =_xlfn.XLOOKUP(A48,[1]Planilha1!$A:$A,[1]Planilha1!$C:$C) -> 219.9
A49: 1223 | B49: Ponteira Pro Tork Modelo Original CBX 250 TWISTER 2002 à 2008 | C49: 177.32 | D49: 164.9076 | E49: ABAIXO DO MERCADO | F49: =_xlfn.XLOOKUP(A49,Planilha1!A:A,Planilha1!E:E) -> 199.9 | G49: =_xlfn.XLOOKUP(A49,[1]Planilha1!$A:$A,[1]Planilha1!$C:$C) -> 199.9
